2022-05-18 12:35:32,483 INFO    MainThread:6756 [internal.py:wandb_internal():93] W&B internal server running at pid: 6756, started at: 2022-05-18 12:35:32.483285
2022-05-18 12:35:32,493 INFO    WriterThread:6756 [datastore.py:open_for_write():75] open: C:\Users\10273\Desktop\大三下\计算摄像学\new\wandb\run-20220518_123531-6657xmei\run-6657xmei.wandb
2022-05-18 12:35:32,493 DEBUG   SenderThread:6756 [sender.py:send():232] send: header
2022-05-18 12:35:32,493 DEBUG   SenderThread:6756 [sender.py:send():232] send: run
2022-05-18 12:35:32,493 INFO    SenderThread:6756 [sender.py:_maybe_setup_resume():490] checking resume status for None/BARNet/6657xmei
2022-05-18 12:35:35,692 ERROR   SenderThread:6756 [retry.py:__call__():126] Retry attempt failed:
Traceback (most recent call last):
  File "D:\install\python\lib\site-packages\urllib3\connectionpool.py", line 700, in urlopen
    self._prepare_proxy(conn)
  File "D:\install\python\lib\site-packages\urllib3\connectionpool.py", line 994, in _prepare_proxy
    conn.connect()
  File "D:\install\python\lib\site-packages\urllib3\connection.py", line 364, in connect
    self.sock = conn = self._connect_tls_proxy(hostname, conn)
  File "D:\install\python\lib\site-packages\urllib3\connection.py", line 505, in _connect_tls_proxy
    ssl_context=ssl_context,
  File "D:\install\python\lib\site-packages\urllib3\util\ssl_.py", line 453, in ssl_wrap_socket
    ssl_sock = _ssl_wrap_socket_impl(sock, context, tls_in_tls)
  File "D:\install\python\lib\site-packages\urllib3\util\ssl_.py", line 495, in _ssl_wrap_socket_impl
    return ssl_context.wrap_socket(sock)
  File "D:\install\python\lib\ssl.py", line 423, in wrap_socket
    session=session
  File "D:\install\python\lib\ssl.py", line 870, in _create
    self.do_handshake()
  File "D:\install\python\lib\ssl.py", line 1139, in do_handshake
    self._sslobj.do_handshake()
OSError: [Errno 0] Error

During handling of the above exception, another exception occurred:

Traceback (most recent call last):
  File "D:\install\python\lib\site-packages\requests\adapters.py", line 450, in send
    timeout=timeout
  File "D:\install\python\lib\site-packages\urllib3\connectionpool.py", line 786, in urlopen
    method, url, error=e, _pool=self, _stacktrace=sys.exc_info()[2]
  File "D:\install\python\lib\site-packages\urllib3\util\retry.py", line 592, in increment
    raise MaxRetryError(_pool, url, error or ResponseError(cause))
urllib3.exceptions.MaxRetryError: HTTPSConnectionPool(host='api.wandb.ai', port=443): Max retries exceeded with url: /graphql (Caused by ProxyError('Cannot connect to proxy.', OSError(0, 'Error')))

During handling of the above exception, another exception occurred:

Traceback (most recent call last):
  File "D:\install\python\lib\site-packages\wandb\sdk\lib\retry.py", line 102, in __call__
    result = self._call_fn(*args, **kwargs)
  File "D:\install\python\lib\site-packages\wandb\sdk\internal\internal_api.py", line 140, in execute
    return self.client.execute(*args, **kwargs)
  File "D:\install\python\lib\site-packages\wandb\vendor\gql-0.2.0\wandb_gql\client.py", line 52, in execute
    result = self._get_result(document, *args, **kwargs)
  File "D:\install\python\lib\site-packages\wandb\vendor\gql-0.2.0\wandb_gql\client.py", line 60, in _get_result
    return self.transport.execute(document, *args, **kwargs)
  File "D:\install\python\lib\site-packages\wandb\vendor\gql-0.2.0\wandb_gql\transport\requests.py", line 38, in execute
    request = requests.post(self.url, **post_args)
  File "D:\install\python\lib\site-packages\requests\api.py", line 117, in post
    return request('post', url, data=data, json=json, **kwargs)
  File "D:\install\python\lib\site-packages\requests\api.py", line 61, in request
    return session.request(method=method, url=url, **kwargs)
  File "D:\install\python\lib\site-packages\requests\sessions.py", line 529, in request
    resp = self.send(prep, **send_kwargs)
  File "D:\install\python\lib\site-packages\requests\sessions.py", line 645, in send
    r = adapter.send(request, **kwargs)
  File "D:\install\python\lib\site-packages\requests\adapters.py", line 513, in send
    raise ProxyError(e, request=request)
requests.exceptions.ProxyError: HTTPSConnectionPool(host='api.wandb.ai', port=443): Max retries exceeded with url: /graphql (Caused by ProxyError('Cannot connect to proxy.', OSError(0, 'Error')))
2022-05-18 12:36:01,428 DEBUG   HandlerThread:6756 [handler.py:handle_request():141] handle_request: shutdown
2022-05-18 12:36:01,428 INFO    HandlerThread:6756 [handler.py:finish():806] shutting down handler
2022-05-18 12:36:01,640 INFO    WriterThread:6756 [datastore.py:close():279] close: C:\Users\10273\Desktop\大三下\计算摄像学\new\wandb\run-20220518_123531-6657xmei\run-6657xmei.wandb
